<?xml version="1.0" encoding="utf-8"?>
<!-- =================================================================================== -->
<!-- |    This document was autogenerated by xacro from plen.urdf.xacro                | -->
<!-- |    EDITING THIS FILE BY HAND IS NOT RECOMMENDED                                 | -->
<!-- =================================================================================== -->
<robot name="plen">
  <gazebo reference="torso">
    <material>Gazebo/Gray</material>
    <mu1>100</mu1>
    <!-- static -->
    <mu2>100</mu2>
    <!-- dynamic -->
    <dampingFactor>0.001</dampingFactor>
    <kp>10000000.0</kp>
    <!-- rigidity (damping) -->
    <kd>1.0</kd>
    <!-- rigidity (damping) -->
    <minDepth>0.001</minDepth>
    <fdir1>1 0 0</fdir1>
    <!-- friction direction -->
  </gazebo>
  <gazebo reference="battery">
    <material>Gazebo/Orange</material>
    <mu1>100</mu1>
    <!-- static -->
    <mu2>100</mu2>
    <!-- dynamic -->
    <dampingFactor>0.001</dampingFactor>
    <kp>10000000.0</kp>
    <!-- rigidity (damping) -->
    <kd>1.0</kd>
    <!-- rigidity (damping) -->
    <minDepth>0.001</minDepth>
    <fdir1>1 0 0</fdir1>
    <!-- friction direction -->
  </gazebo>
  <gazebo reference="head">
    <material>Gazebo/Gray</material>
    <mu1>100</mu1>
    <!-- static -->
    <mu2>100</mu2>
    <!-- dynamic -->
    <dampingFactor>0.001</dampingFactor>
    <kp>10000000.0</kp>
    <!-- rigidity (damping) -->
    <kd>1.0</kd>
    <!-- rigidity (damping) -->
    <minDepth>0.001</minDepth>
    <fdir1>1 0 0</fdir1>
    <!-- friction direction -->
  </gazebo>
  <gazebo reference="rt_servo">
    <material>Gazebo/Orange</material>
    <mu1>100</mu1>
    <!-- static -->
    <mu2>100</mu2>
    <!-- dynamic -->
    <dampingFactor>0.001</dampingFactor>
    <kp>10000000.0</kp>
    <!-- rigidity (damping) -->
    <kd>1.0</kd>
    <!-- rigidity (damping) -->
    <minDepth>0.001</minDepth>
    <fdir1>1 0 0</fdir1>
    <!-- friction direction -->
  </gazebo>
  <gazebo reference="lt_servo">
    <material>Gazebo/Orange</material>
    <mu1>100</mu1>
    <!-- static -->
    <mu2>100</mu2>
    <!-- dynamic -->
    <dampingFactor>0.001</dampingFactor>
    <kp>10000000.0</kp>
    <!-- rigidity (damping) -->
    <kd>1.0</kd>
    <!-- rigidity (damping) -->
    <minDepth>0.001</minDepth>
    <fdir1>1 0 0</fdir1>
    <!-- friction direction -->
  </gazebo>
  <gazebo reference="rb_servo">
    <material>Gazebo/Orange</material>
    <mu1>100</mu1>
    <!-- static -->
    <mu2>100</mu2>
    <!-- dynamic -->
    <dampingFactor>0.001</dampingFactor>
    <kp>10000000.0</kp>
    <!-- rigidity (damping) -->
    <kd>1.0</kd>
    <!-- rigidity (damping) -->
    <minDepth>0.001</minDepth>
    <fdir1>1 0 0</fdir1>
    <!-- friction direction -->
  </gazebo>
  <gazebo reference="lb_servo">
    <material>Gazebo/Orange</material>
    <mu1>100</mu1>
    <!-- static -->
    <mu2>100</mu2>
    <!-- dynamic -->
    <dampingFactor>0.001</dampingFactor>
    <kp>10000000.0</kp>
    <!-- rigidity (damping) -->
    <kd>1.0</kd>
    <!-- rigidity (damping) -->
    <minDepth>0.001</minDepth>
    <fdir1>1 0 0</fdir1>
    <!-- friction direction -->
  </gazebo>
  <gazebo reference="r_shoulder">
    <material>Gazebo/Gray</material>
    <mu1>100</mu1>
    <!-- static -->
    <mu2>100</mu2>
    <!-- dynamic -->
    <dampingFactor>0.001</dampingFactor>
    <kp>10000000.0</kp>
    <!-- rigidity (damping) -->
    <kd>1.0</kd>
    <!-- rigidity (damping) -->
    <minDepth>0.001</minDepth>
    <fdir1>1 0 0</fdir1>
    <!-- friction direction -->
  </gazebo>
  <gazebo reference="rs_servo">
    <material>Gazebo/Orange</material>
    <mu1>100</mu1>
    <!-- static -->
    <mu2>100</mu2>
    <!-- dynamic -->
    <dampingFactor>0.001</dampingFactor>
    <kp>10000000.0</kp>
    <!-- rigidity (damping) -->
    <kd>1.0</kd>
    <!-- rigidity (damping) -->
    <minDepth>0.001</minDepth>
    <fdir1>1 0 0</fdir1>
    <!-- friction direction -->
  </gazebo>
  <gazebo reference="r_arm">
    <material>Gazebo/Gray</material>
    <mu1>100</mu1>
    <!-- static -->
    <mu2>100</mu2>
    <!-- dynamic -->
    <dampingFactor>0.001</dampingFactor>
    <kp>10000000.0</kp>
    <!-- rigidity (damping) -->
    <kd>1.0</kd>
    <!-- rigidity (damping) -->
    <minDepth>0.001</minDepth>
    <fdir1>1 0 0</fdir1>
    <!-- friction direction -->
  </gazebo>
  <gazebo reference="re_servo">
    <material>Gazebo/Orange</material>
    <mu1>100</mu1>
    <!-- static -->
    <mu2>100</mu2>
    <!-- dynamic -->
    <dampingFactor>0.001</dampingFactor>
    <kp>10000000.0</kp>
    <!-- rigidity (damping) -->
    <kd>1.0</kd>
    <!-- rigidity (damping) -->
    <minDepth>0.001</minDepth>
    <fdir1>1 0 0</fdir1>
    <!-- friction direction -->
  </gazebo>
  <gazebo reference="r_elbow">
    <material>Gazebo/Gray</material>
    <mu1>100</mu1>
    <!-- static -->
    <mu2>100</mu2>
    <!-- dynamic -->
    <dampingFactor>0.001</dampingFactor>
    <kp>10000000.0</kp>
    <!-- rigidity (damping) -->
    <kd>1.0</kd>
    <!-- rigidity (damping) -->
    <minDepth>0.001</minDepth>
    <fdir1>1 0 0</fdir1>
    <!-- friction direction -->
  </gazebo>
  <gazebo reference="r_hand">
    <material>Gazebo/Gray</material>
    <mu1>100</mu1>
    <!-- static -->
    <mu2>100</mu2>
    <!-- dynamic -->
    <dampingFactor>0.001</dampingFactor>
    <kp>10000000.0</kp>
    <!-- rigidity (damping) -->
    <kd>1.0</kd>
    <!-- rigidity (damping) -->
    <minDepth>0.001</minDepth>
    <fdir1>1 0 0</fdir1>
    <!-- friction direction -->
  </gazebo>
  <gazebo reference="l_shoulder">
    <material>Gazebo/Gray</material>
    <mu1>100</mu1>
    <!-- static -->
    <mu2>100</mu2>
    <!-- dynamic -->
    <dampingFactor>0.001</dampingFactor>
    <kp>10000000.0</kp>
    <!-- rigidity (damping) -->
    <kd>1.0</kd>
    <!-- rigidity (damping) -->
    <minDepth>0.001</minDepth>
    <fdir1>1 0 0</fdir1>
    <!-- friction direction -->
  </gazebo>
  <gazebo reference="ls_servo">
    <material>Gazebo/Orange</material>
    <mu1>100</mu1>
    <!-- static -->
    <mu2>100</mu2>
    <!-- dynamic -->
    <dampingFactor>0.001</dampingFactor>
    <kp>10000000.0</kp>
    <!-- rigidity (damping) -->
    <kd>1.0</kd>
    <!-- rigidity (damping) -->
    <minDepth>0.001</minDepth>
    <fdir1>1 0 0</fdir1>
    <!-- friction direction -->
  </gazebo>
  <gazebo reference="l_arm">
    <material>Gazebo/Gray</material>
    <mu1>100</mu1>
    <!-- static -->
    <mu2>100</mu2>
    <!-- dynamic -->
    <dampingFactor>0.001</dampingFactor>
    <kp>10000000.0</kp>
    <!-- rigidity (damping) -->
    <kd>1.0</kd>
    <!-- rigidity (damping) -->
    <minDepth>0.001</minDepth>
    <fdir1>1 0 0</fdir1>
    <!-- friction direction -->
  </gazebo>
  <gazebo reference="le_servo">
    <material>Gazebo/Orange</material>
    <mu1>100</mu1>
    <!-- static -->
    <mu2>100</mu2>
    <!-- dynamic -->
    <dampingFactor>0.001</dampingFactor>
    <kp>10000000.0</kp>
    <!-- rigidity (damping) -->
    <kd>1.0</kd>
    <!-- rigidity (damping) -->
    <minDepth>0.001</minDepth>
    <fdir1>1 0 0</fdir1>
    <!-- friction direction -->
  </gazebo>
  <gazebo reference="l_elbow">
    <material>Gazebo/Gray</material>
    <mu1>100</mu1>
    <!-- static -->
    <mu2>100</mu2>
    <!-- dynamic -->
    <dampingFactor>0.001</dampingFactor>
    <kp>10000000.0</kp>
    <!-- rigidity (damping) -->
    <kd>1.0</kd>
    <!-- rigidity (damping) -->
    <minDepth>0.001</minDepth>
    <fdir1>1 0 0</fdir1>
    <!-- friction direction -->
  </gazebo>
  <gazebo reference="l_hand">
    <material>Gazebo/Gray</material>
    <mu1>100</mu1>
    <!-- static -->
    <mu2>100</mu2>
    <!-- dynamic -->
    <dampingFactor>0.001</dampingFactor>
    <kp>10000000.0</kp>
    <!-- rigidity (damping) -->
    <kd>1.0</kd>
    <!-- rigidity (damping) -->
    <minDepth>0.001</minDepth>
    <fdir1>1 0 0</fdir1>
    <!-- friction direction -->
  </gazebo>
  <gazebo reference="r_hip">
    <material>Gazebo/Gray</material>
    <mu1>100</mu1>
    <!-- static -->
    <mu2>100</mu2>
    <!-- dynamic -->
    <dampingFactor>0.001</dampingFactor>
    <kp>10000000.0</kp>
    <!-- rigidity (damping) -->
    <kd>1.0</kd>
    <!-- rigidity (damping) -->
    <minDepth>0.001</minDepth>
    <fdir1>1 0 0</fdir1>
    <!-- friction direction -->
  </gazebo>
  <gazebo reference="r_thigh">
    <material>Gazebo/Orange</material>
    <mu1>100</mu1>
    <!-- static -->
    <mu2>100</mu2>
    <!-- dynamic -->
    <dampingFactor>0.001</dampingFactor>
    <kp>10000000.0</kp>
    <!-- rigidity (damping) -->
    <kd>1.0</kd>
    <!-- rigidity (damping) -->
    <minDepth>0.001</minDepth>
    <fdir1>1 0 0</fdir1>
    <!-- friction direction -->
  </gazebo>
  <gazebo reference="r_knee">
    <material>Gazebo/Gray</material>
    <mu1>100</mu1>
    <!-- static -->
    <mu2>100</mu2>
    <!-- dynamic -->
    <dampingFactor>0.001</dampingFactor>
    <kp>10000000.0</kp>
    <!-- rigidity (damping) -->
    <kd>1.0</kd>
    <!-- rigidity (damping) -->
    <minDepth>0.001</minDepth>
    <fdir1>1 0 0</fdir1>
    <!-- friction direction -->
  </gazebo>
  <gazebo reference="r_knee_servo">
    <material>Gazebo/Orange</material>
    <mu1>100</mu1>
    <!-- static -->
    <mu2>100</mu2>
    <!-- dynamic -->
    <dampingFactor>0.001</dampingFactor>
    <kp>10000000.0</kp>
    <!-- rigidity (damping) -->
    <kd>1.0</kd>
    <!-- rigidity (damping) -->
    <minDepth>0.001</minDepth>
    <fdir1>1 0 0</fdir1>
    <!-- friction direction -->
  </gazebo>
  <gazebo reference="r_shin">
    <material>Gazebo/Gray</material>
    <mu1>100</mu1>
    <!-- static -->
    <mu2>100</mu2>
    <!-- dynamic -->
    <dampingFactor>0.001</dampingFactor>
    <kp>10000000.0</kp>
    <!-- rigidity (damping) -->
    <kd>1.0</kd>
    <!-- rigidity (damping) -->
    <minDepth>0.001</minDepth>
    <fdir1>1 0 0</fdir1>
    <!-- friction direction -->
  </gazebo>
  <gazebo reference="r_ankle">
    <material>Gazebo/Orange</material>
    <mu1>100</mu1>
    <!-- static -->
    <mu2>100</mu2>
    <!-- dynamic -->
    <dampingFactor>0.001</dampingFactor>
    <kp>10000000.0</kp>
    <!-- rigidity (damping) -->
    <kd>1.0</kd>
    <!-- rigidity (damping) -->
    <minDepth>0.001</minDepth>
    <fdir1>1 0 0</fdir1>
    <!-- friction direction -->
  </gazebo>
  <gazebo reference="r_foot">
    <material>Gazebo/Gray</material>
    <mu1>100</mu1>
    <!-- static -->
    <mu2>100</mu2>
    <!-- dynamic -->
    <dampingFactor>0.001</dampingFactor>
    <kp>10000000.0</kp>
    <!-- rigidity (damping) -->
    <kd>1.0</kd>
    <!-- rigidity (damping) -->
    <minDepth>0.001</minDepth>
    <fdir1>1 0 0</fdir1>
    <!-- friction direction -->
  </gazebo>
  <gazebo reference="l_hip">
    <material>Gazebo/Gray</material>
    <mu1>100</mu1>
    <!-- static -->
    <mu2>100</mu2>
    <!-- dynamic -->
    <dampingFactor>0.001</dampingFactor>
    <kp>10000000.0</kp>
    <!-- rigidity (damping) -->
    <kd>1.0</kd>
    <!-- rigidity (damping) -->
    <minDepth>0.001</minDepth>
    <fdir1>1 0 0</fdir1>
    <!-- friction direction -->
  </gazebo>
  <gazebo reference="l_thigh">
    <material>Gazebo/Orange</material>
    <mu1>100</mu1>
    <!-- static -->
    <mu2>100</mu2>
    <!-- dynamic -->
    <dampingFactor>0.001</dampingFactor>
    <kp>10000000.0</kp>
    <!-- rigidity (damping) -->
    <kd>1.0</kd>
    <!-- rigidity (damping) -->
    <minDepth>0.001</minDepth>
    <fdir1>1 0 0</fdir1>
    <!-- friction direction -->
  </gazebo>
  <gazebo reference="l_knee">
    <material>Gazebo/Gray</material>
    <mu1>100</mu1>
    <!-- static -->
    <mu2>100</mu2>
    <!-- dynamic -->
    <dampingFactor>0.001</dampingFactor>
    <kp>10000000.0</kp>
    <!-- rigidity (damping) -->
    <kd>1.0</kd>
    <!-- rigidity (damping) -->
    <minDepth>0.001</minDepth>
    <fdir1>1 0 0</fdir1>
    <!-- friction direction -->
  </gazebo>
  <gazebo reference="l_knee_servo">
    <material>Gazebo/Orange</material>
    <mu1>100</mu1>
    <!-- static -->
    <mu2>100</mu2>
    <!-- dynamic -->
    <dampingFactor>0.001</dampingFactor>
    <kp>10000000.0</kp>
    <!-- rigidity (damping) -->
    <kd>1.0</kd>
    <!-- rigidity (damping) -->
    <minDepth>0.001</minDepth>
    <fdir1>1 0 0</fdir1>
    <!-- friction direction -->
  </gazebo>
  <gazebo reference="l_shin">
    <material>Gazebo/Gray</material>
    <mu1>100</mu1>
    <!-- static -->
    <mu2>100</mu2>
    <!-- dynamic -->
    <dampingFactor>0.001</dampingFactor>
    <kp>10000000.0</kp>
    <!-- rigidity (damping) -->
    <kd>1.0</kd>
    <!-- rigidity (damping) -->
    <minDepth>0.001</minDepth>
    <fdir1>1 0 0</fdir1>
    <!-- friction direction -->
  </gazebo>
  <gazebo reference="l_ankle">
    <material>Gazebo/Orange</material>
    <mu1>100</mu1>
    <!-- static -->
    <mu2>100</mu2>
    <!-- dynamic -->
    <dampingFactor>0.001</dampingFactor>
    <kp>10000000.0</kp>
    <!-- rigidity (damping) -->
    <kd>1.0</kd>
    <!-- rigidity (damping) -->
    <minDepth>0.001</minDepth>
    <fdir1>1 0 0</fdir1>
    <!-- friction direction -->
  </gazebo>
  <gazebo reference="l_foot">
    <material>Gazebo/Gray</material>
    <mu1>100</mu1>
    <!-- static -->
    <mu2>100</mu2>
    <!-- dynamic -->
    <dampingFactor>0.001</dampingFactor>
    <kp>10000000.0</kp>
    <!-- rigidity (damping) -->
    <kd>1.0</kd>
    <!-- rigidity (damping) -->
    <minDepth>0.001</minDepth>
    <fdir1>1 0 0</fdir1>
    <!-- friction direction -->
  </gazebo>
  <!-- Robot description -->
  <!-- Links -->
  <link name="torso">
    <visual>
      <origin rpy="0 0 0" xyz="0 0 0"/>
      <geometry>
        <mesh filename="package://plen_ros/meshes_bin/torso.stl" scale="0.001 0.001 0.001"/>
      </geometry>
      <material name="red_mat">
        <color rgba="0 0 0 1"/>
      </material>
    </visual>
    <collision>
      <origin rpy="0 0 0" xyz="0.0 0 0.0"/>
      <geometry>
        <box size="0.045 0.048 0.075"/>
      </geometry>
    </collision>
    <inertial>
      <mass value="0.043968"/>
      <origin rpy="0 0 0" xyz="0.0 0 0.0"/>
      <!-- Inertial Axes -->
      <inertia ixx="2.80296e-05" ixy="0" ixz="0" iyx="0" iyy="2.80296e-05" iyz="0" izx="0" izy="0" izz="1.5861456e-05"/>
    </inertial>
  </link>
  <!-- m to mm -->
  <link name="battery">
    <visual>
      <origin rpy="0 0 0" xyz="0 0 0"/>
      <geometry>
        <mesh filename="package://plen_ros/meshes_bin/battery.stl" scale="0.001 0.001 0.001"/>
      </geometry>
      <material name="green_mat">
        <color rgba="1 0.49 0 1"/>
      </material>
    </visual>
    <collision>
      <origin rpy="0 0 0" xyz="0.0075 0 0.0115"/>
      <geometry>
        <box size="0.011 0.051 0.046"/>
      </geometry>
    </collision>
    <inertial>
      <mass value="0.064"/>
      <origin rpy="0 0 0" xyz="0.0075 0 0.0115"/>
      <!-- Inertial Axes -->
      <inertia ixx="1.19306666667e-05" ixy="0" ixz="0" iyx="0" iyy="1.19306666667e-05" iyz="0" izx="0" izy="0" izz="1.45173333333e-05"/>
    </inertial>
  </link>
  <link name="head">
    <visual>
      <origin rpy="0 0 0" xyz="0 0 0"/>
      <geometry>
        <mesh filename="package://plen_ros/meshes_bin/head.stl" scale="0.001 0.001 0.001"/>
      </geometry>
      <material name="green_mat">
        <color rgba="0.42 0.05 0.68 1"/>
      </material>
    </visual>
    <collision>
      <origin rpy="0 0 0" xyz="0 0 0.0"/>
      <geometry>
        <box size="0.04 0.04 0.04"/>
      </geometry>
    </collision>
    <inertial>
      <mass value="0.01"/>
      <origin rpy="0 0 0" xyz="0.0 0 0.0"/>
      <!-- Inertial Axes -->
      <inertia ixx="2.66666666667e-06" ixy="0" ixz="0" iyx="0" iyy="2.66666666667e-06" iyz="0" izx="0" izy="0" izz="2.66666666667e-06"/>
    </inertial>
  </link>
  <link name="rt_servo">
    <visual>
      <origin rpy="0 0 3.14159265359" xyz="0 0 0"/>
      <geometry>
        <mesh filename="package://plen_ros/meshes_bin/servo.stl" scale="0.001 0.001 0.001"/>
      </geometry>
      <material name="blue_mat">
        <color rgba="1 0.49 0 1"/>
      </material>
    </visual>
    <collision>
      <origin rpy="0 0 3.14159265359" xyz="0 0.00625 0.0"/>
      <geometry>
        <box size="0.012 0.025 0.025"/>
      </geometry>
    </collision>
    <inertial>
      <mass value="0.012"/>
      <origin rpy="0 0 0" xyz="0 0.00625 0.0"/>
      <!-- Inertial Axes -->
      <inertia ixx="7.69e-07" ixy="0" ixz="0" iyx="0" iyy="7.69e-07" iyz="0" izx="0" izy="0" izz="7.69e-07"/>
    </inertial>
  </link>
  <link name="lt_servo">
    <visual>
      <origin rpy="0 0 3.14159265359" xyz="0 0 0"/>
      <geometry>
        <mesh filename="package://plen_ros/meshes_bin/servo.stl" scale="0.001 0.001 0.001"/>
      </geometry>
      <material name="blue_mat">
        <color rgba="1 0.49 0 1"/>
      </material>
    </visual>
    <collision>
      <origin rpy="0 0 3.14159265359" xyz="0 0.00625 0.0"/>
      <geometry>
        <box size="0.012 0.025 0.025"/>
      </geometry>
    </collision>
    <inertial>
      <mass value="0.012"/>
      <origin rpy="0 0 0" xyz="0 0.00625 0.0"/>
      <!-- Inertial Axes -->
      <inertia ixx="7.69e-07" ixy="0" ixz="0" iyx="0" iyy="7.69e-07" iyz="0" izx="0" izy="0" izz="7.69e-07"/>
    </inertial>
  </link>
  <link name="rb_servo">
    <visual>
      <origin rpy="0 0 3.14159265359" xyz="0 0 0"/>
      <geometry>
        <mesh filename="package://plen_ros/meshes_bin/servo.stl" scale="0.001 0.001 0.001"/>
      </geometry>
      <material name="blue_mat">
        <color rgba="1 0.49 0 1"/>
      </material>
    </visual>
    <collision>
      <origin rpy="0 0 3.14159265359" xyz="0 0.00625 0.0"/>
      <geometry>
        <box size="0.012 0.025 0.025"/>
      </geometry>
    </collision>
    <inertial>
      <mass value="0.012"/>
      <origin rpy="0 0 0" xyz="0 0.00625 0.0"/>
      <!-- Inertial Axes -->
      <inertia ixx="7.69e-07" ixy="0" ixz="0" iyx="0" iyy="7.69e-07" iyz="0" izx="0" izy="0" izz="7.69e-07"/>
    </inertial>
  </link>
  <link name="lb_servo">
    <visual>
      <origin rpy="0 0 3.14159265359" xyz="0 0 0"/>
      <geometry>
        <mesh filename="package://plen_ros/meshes_bin/servo.stl" scale="0.001 0.001 0.001"/>
      </geometry>
      <material name="blue_mat">
        <color rgba="1 0.49 0 1"/>
      </material>
    </visual>
    <collision>
      <origin rpy="0 0 3.14159265359" xyz="0 0.00625 0.0"/>
      <geometry>
        <box size="0.012 0.025 0.025"/>
      </geometry>
    </collision>
    <inertial>
      <mass value="0.012"/>
      <origin rpy="0 0 0" xyz="0 0.00625 0.0"/>
      <!-- Inertial Axes -->
      <inertia ixx="7.69e-07" ixy="0" ixz="0" iyx="0" iyy="7.69e-07" iyz="0" izx="0" izy="0" izz="7.69e-07"/>
    </inertial>
  </link>
  <link name="r_shoulder">
    <visual>
      <origin rpy="0 0 0" xyz="0 0 0"/>
      <geometry>
        <mesh filename="package://plen_ros/meshes_bin/shoulder.stl" scale="0.001 0.001 0.001"/>
      </geometry>
      <material name="green_mat">
        <color rgba="0.42 0.05 0.68 1"/>
      </material>
    </visual>
    <collision>
      <origin rpy="0 0 0" xyz="0 0 0.0125"/>
      <geometry>
        <box size="0.018 0.035 0.025"/>
      </geometry>
    </collision>
    <inertial>
      <mass value="0.002954"/>
      <origin rpy="0 0 0" xyz="0 0 0.0125"/>
      <!-- Inertial Axes -->
      <inertia ixx="2.33612166667e-07" ixy="0" ixz="0" iyx="0" iyy="2.33612166667e-07" iyz="0" izx="0" izy="0" izz="3.81312166667e-07"/>
    </inertial>
  </link>
  <link name="rs_servo">
    <visual>
      <origin rpy="0 0 3.14159265359" xyz="0 0 0"/>
      <geometry>
        <mesh filename="package://plen_ros/meshes_bin/servo.stl" scale="0.001 0.001 0.001"/>
      </geometry>
      <material name="blue_mat">
        <color rgba="1 0.49 0 1"/>
      </material>
    </visual>
    <collision>
      <origin rpy="0 0 3.14159265359" xyz="0 0.00625 0.0"/>
      <geometry>
        <box size="0.012 0.025 0.025"/>
      </geometry>
    </collision>
    <inertial>
      <mass value="0.012"/>
      <origin rpy="0 0 0" xyz="0 0.00625 0.0"/>
      <!-- Inertial Axes -->
      <inertia ixx="7.69e-07" ixy="0" ixz="0" iyx="0" iyy="7.69e-07" iyz="0" izx="0" izy="0" izz="7.69e-07"/>
    </inertial>
  </link>
  <link name="r_arm">
    <visual>
      <origin rpy="0 0 0" xyz="0 0 0"/>
      <geometry>
        <mesh filename="package://plen_ros/meshes_bin/arm.stl" scale="0.001 0.001 0.001"/>
      </geometry>
      <material name="red_mat">
        <color rgba="0 0 0 1"/>
      </material>
    </visual>
    <collision>
      <origin rpy="0 0 0" xyz="0 0 0.0"/>
      <geometry>
        <box size="0.015 0.035 0.05"/>
      </geometry>
    </collision>
    <inertial>
      <mass value="0.005091"/>
      <origin rpy="0 0 0" xyz="0 0 0.0"/>
      <!-- Inertial Axes -->
      <inertia ixx="1.15608125e-06" ixy="0" ixz="0" iyx="0" iyy="1.15608125e-06" iyz="0" izx="0" izy="0" izz="6.151625e-07"/>
    </inertial>
  </link>
  <link name="re_servo">
    <visual>
      <origin rpy="0 0 3.14159265359" xyz="0 0 0"/>
      <geometry>
        <mesh filename="package://plen_ros/meshes_bin/servo.stl" scale="0.001 0.001 0.001"/>
      </geometry>
      <material name="blue_mat">
        <color rgba="1 0.49 0 1"/>
      </material>
    </visual>
    <collision>
      <origin rpy="0 0 3.14159265359" xyz="0 0.00625 0.0"/>
      <geometry>
        <box size="0.012 0.025 0.025"/>
      </geometry>
    </collision>
    <inertial>
      <mass value="0.012"/>
      <origin rpy="0 0 0" xyz="0 0.00625 0.0"/>
      <!-- Inertial Axes -->
      <inertia ixx="7.69e-07" ixy="0" ixz="0" iyx="0" iyy="7.69e-07" iyz="0" izx="0" izy="0" izz="7.69e-07"/>
    </inertial>
  </link>
  <link name="r_elbow">
    <visual>
      <origin rpy="0 0 0" xyz="-0.0135 0 0"/>
      <geometry>
        <mesh filename="package://plen_ros/meshes_bin/elbow.stl" scale="0.001 0.001 0.001"/>
      </geometry>
      <material name="green_mat">
        <color rgba="0.42 0.05 0.68 1"/>
      </material>
    </visual>
    <collision>
      <origin rpy="0 0 0" xyz="-0.00675 0 0.0"/>
      <geometry>
        <box size="0.027 0.034 0.014"/>
      </geometry>
    </collision>
    <inertial>
      <mass value="0.003046"/>
      <origin rpy="0 0 0" xyz="-0.00675 0 0.0"/>
      <!-- Inertial Axes -->
      <inertia ixx="2.34795833333e-07" ixy="0" ixz="0" iyx="0" iyy="2.34795833333e-07" iyz="0" izx="0" izy="0" izz="4.78475833333e-07"/>
    </inertial>
  </link>
  <link name="r_hand">
    <visual>
      <origin rpy="0 0 0" xyz="0.0 0 0"/>
      <geometry>
        <mesh filename="package://plen_ros/meshes_bin/hand.stl" scale="0.001 0.001 0.001"/>
      </geometry>
      <material name="red_mat">
        <color rgba="0 0 0 1"/>
      </material>
    </visual>
    <collision>
      <origin rpy="0 0 0" xyz="0 0 0.0"/>
      <geometry>
        <box size="0.019 0.034 0.035"/>
      </geometry>
    </collision>
    <inertial>
      <mass value="0.008305"/>
      <origin rpy="0 0 0" xyz="0 0 0.0"/>
      <!-- Inertial Axes -->
      <inertia ixx="1.09764416667e-06" ixy="0" ixz="0" iyx="0" iyy="1.09764416667e-06" iyz="0" izx="0" izy="0" izz="1.04989041667e-06"/>
    </inertial>
  </link>
  <link name="l_shoulder">
    <visual>
      <origin rpy="0 0 0" xyz="0 0 0"/>
      <geometry>
        <mesh filename="package://plen_ros/meshes_bin/shoulder.stl" scale="0.001 0.001 0.001"/>
      </geometry>
      <material name="green_mat">
        <color rgba="0.42 0.05 0.68 1"/>
      </material>
    </visual>
    <collision>
      <origin rpy="0 0 0" xyz="0 0 0.0125"/>
      <geometry>
        <box size="0.018 0.035 0.025"/>
      </geometry>
    </collision>
    <inertial>
      <mass value="0.002954"/>
      <origin rpy="0 0 0" xyz="0 0 0.0125"/>
      <!-- Inertial Axes -->
      <inertia ixx="2.33612166667e-07" ixy="0" ixz="0" iyx="0" iyy="2.33612166667e-07" iyz="0" izx="0" izy="0" izz="3.81312166667e-07"/>
    </inertial>
  </link>
  <link name="ls_servo">
    <visual>
      <origin rpy="0 0 3.14159265359" xyz="0 0 0"/>
      <geometry>
        <mesh filename="package://plen_ros/meshes_bin/servo.stl" scale="0.001 0.001 0.001"/>
      </geometry>
      <material name="blue_mat">
        <color rgba="1 0.49 0 1"/>
      </material>
    </visual>
    <collision>
      <origin rpy="0 0 3.14159265359" xyz="0 0.00625 0.0"/>
      <geometry>
        <box size="0.012 0.025 0.025"/>
      </geometry>
    </collision>
    <inertial>
      <mass value="0.012"/>
      <origin rpy="0 0 0" xyz="0 0.00625 0.0"/>
      <!-- Inertial Axes -->
      <inertia ixx="7.69e-07" ixy="0" ixz="0" iyx="0" iyy="7.69e-07" iyz="0" izx="0" izy="0" izz="7.69e-07"/>
    </inertial>
  </link>
  <link name="l_arm">
    <visual>
      <origin rpy="0 0 0" xyz="0 0 0"/>
      <geometry>
        <mesh filename="package://plen_ros/meshes_bin/arm.stl" scale="0.001 0.001 0.001"/>
      </geometry>
      <material name="red_mat">
        <color rgba="0 0 0 1"/>
      </material>
    </visual>
    <collision>
      <origin rpy="0 0 0" xyz="0 0 0.0"/>
      <geometry>
        <box size="0.015 0.035 0.05"/>
      </geometry>
    </collision>
    <inertial>
      <mass value="0.005091"/>
      <origin rpy="0 0 0" xyz="0 0 0.0"/>
      <!-- Inertial Axes -->
      <inertia ixx="1.15608125e-06" ixy="0" ixz="0" iyx="0" iyy="1.15608125e-06" iyz="0" izx="0" izy="0" izz="6.151625e-07"/>
    </inertial>
  </link>
  <link name="le_servo">
    <visual>
      <origin rpy="0 0 3.14159265359" xyz="0 0 0"/>
      <geometry>
        <mesh filename="package://plen_ros/meshes_bin/servo.stl" scale="0.001 0.001 0.001"/>
      </geometry>
      <material name="blue_mat">
        <color rgba="1 0.49 0 1"/>
      </material>
    </visual>
    <collision>
      <origin rpy="0 0 3.14159265359" xyz="0 0.00625 0.0"/>
      <geometry>
        <box size="0.012 0.025 0.025"/>
      </geometry>
    </collision>
    <inertial>
      <mass value="0.012"/>
      <origin rpy="0 0 0" xyz="0 0.00625 0.0"/>
      <!-- Inertial Axes -->
      <inertia ixx="7.69e-07" ixy="0" ixz="0" iyx="0" iyy="7.69e-07" iyz="0" izx="0" izy="0" izz="7.69e-07"/>
    </inertial>
  </link>
  <link name="l_elbow">
    <visual>
      <origin rpy="0 0 0" xyz="-0.0135 0 0"/>
      <geometry>
        <mesh filename="package://plen_ros/meshes_bin/elbow.stl" scale="0.001 0.001 0.001"/>
      </geometry>
      <material name="green_mat">
        <color rgba="0.42 0.05 0.68 1"/>
      </material>
    </visual>
    <collision>
      <origin rpy="0 0 0" xyz="-0.00675 0 0.0"/>
      <geometry>
        <box size="0.027 0.034 0.014"/>
      </geometry>
    </collision>
    <inertial>
      <mass value="0.003046"/>
      <origin rpy="0 0 0" xyz="-0.00675 0 0.0"/>
      <!-- Inertial Axes -->
      <inertia ixx="2.34795833333e-07" ixy="0" ixz="0" iyx="0" iyy="2.34795833333e-07" iyz="0" izx="0" izy="0" izz="4.78475833333e-07"/>
    </inertial>
  </link>
  <link name="l_hand">
    <visual>
      <origin rpy="0 0 0" xyz="0.0 0 0"/>
      <geometry>
        <mesh filename="package://plen_ros/meshes_bin/hand.stl" scale="0.001 0.001 0.001"/>
      </geometry>
      <material name="red_mat">
        <color rgba="0 0 0 1"/>
      </material>
    </visual>
    <collision>
      <origin rpy="0 0 0" xyz="0 0 0.0"/>
      <geometry>
        <box size="0.019 0.034 0.035"/>
      </geometry>
    </collision>
    <inertial>
      <mass value="0.008305"/>
      <origin rpy="0 0 0" xyz="0 0 0.0"/>
      <!-- Inertial Axes -->
      <inertia ixx="1.09764416667e-06" ixy="0" ixz="0" iyx="0" iyy="1.09764416667e-06" iyz="0" izx="0" izy="0" izz="1.04989041667e-06"/>
    </inertial>
  </link>
  <link name="r_hip">
    <visual>
      <origin rpy="3.14159265359 0 3.14159265359" xyz="0.0 0.0 0.0"/>
      <geometry>
        <mesh filename="package://plen_ros/meshes_bin/rhip.stl" scale="0.001 0.001 0.001"/>
      </geometry>
      <material name="blue_mat">
        <color rgba="1 0.49 0 1"/>
      </material>
    </visual>
    <collision>
      <origin rpy="3.14159265359 0 3.14159265359" xyz="0 0 -0.009"/>
      <geometry>
        <box size="0.025 0.035 0.018"/>
      </geometry>
    </collision>
    <inertial>
      <mass value="0.002568"/>
      <origin rpy="0 0 0" xyz="0 0 -0.009"/>
      <!-- Inertial Axes -->
      <inertia ixx="2.03086e-07" ixy="0" ixz="0" iyx="0" iyy="2.03086e-07" iyz="0" izx="0" izy="0" izz="3.959e-07"/>
    </inertial>
  </link>
  <link name="r_thigh">
    <visual>
      <origin rpy="0 0 0" xyz="-0.0075 0 -0.0075"/>
      <geometry>
        <mesh filename="package://plen_ros/meshes_bin/rthigh.stl" scale="0.001 0.001 0.001"/>
      </geometry>
      <material name="green_mat">
        <color rgba="0.42 0.05 0.68 1"/>
      </material>
    </visual>
    <collision>
      <origin rpy="0 0 0" xyz="-0.007 0 0.007"/>
      <geometry>
        <box size="0.028 0.028 0.028"/>
      </geometry>
    </collision>
    <inertial>
      <mass value="0.04"/>
      <origin rpy="0 0 0" xyz="-0.007 0 0.007"/>
      <!-- Inertial Axes -->
      <inertia ixx="5.22666666667e-06" ixy="0" ixz="0" iyx="0" iyy="5.22666666667e-06" iyz="0" izx="0" izy="0" izz="5.22666666667e-06"/>
    </inertial>
  </link>
  <!-- og mass: 21.617-->
  <link name="r_knee">
    <visual>
      <origin rpy="0 0 0" xyz="0.0 0.0 0.0"/>
      <geometry>
        <mesh filename="package://plen_ros/meshes_bin/rknee.stl" scale="0.001 0.001 0.001"/>
      </geometry>
      <material name="red_mat">
        <color rgba="0 0 0 1"/>
      </material>
    </visual>
    <collision>
      <origin rpy="0 0 0" xyz="0.0175 -0.015 0.0"/>
      <geometry>
        <box size="0.038 0.03 0.024"/>
      </geometry>
    </collision>
    <inertial>
      <mass value="0.005004"/>
      <origin rpy="0 0 0" xyz="0.0175 -0.015 0.0"/>
      <!-- Inertial Axes -->
      <inertia ixx="8.4234e-07" ixy="0" ixz="0" iyx="0" iyy="8.4234e-07" iyz="0" izx="0" izy="0" izz="9.77448e-07"/>
    </inertial>
  </link>
  <link name="r_knee_servo">
    <visual>
      <origin rpy="0 0 3.14159265359" xyz="0 0 0"/>
      <geometry>
        <mesh filename="package://plen_ros/meshes_bin/servo.stl" scale="0.001 0.001 0.001"/>
      </geometry>
      <material name="blue_mat">
        <color rgba="1 0.49 0 1"/>
      </material>
    </visual>
    <collision>
      <origin rpy="0 0 3.14159265359" xyz="0 0.00625 0.0"/>
      <geometry>
        <box size="0.012 0.025 0.025"/>
      </geometry>
    </collision>
    <inertial>
      <mass value="0.012"/>
      <origin rpy="0 0 0" xyz="0 0.00625 0.0"/>
      <!-- Inertial Axes -->
      <inertia ixx="7.69e-07" ixy="0" ixz="0" iyx="0" iyy="7.69e-07" iyz="0" izx="0" izy="0" izz="7.69e-07"/>
    </inertial>
  </link>
  <link name="r_shin">
    <visual>
      <origin rpy="0 0 0" xyz="0.0168 0 -0.0091"/>
      <geometry>
        <mesh filename="package://plen_ros/meshes_bin/rshin.stl" scale="0.001 0.001 0.001"/>
      </geometry>
      <material name="blue_mat">
        <color rgba="1 0.49 0 1"/>
      </material>
    </visual>
    <collision>
      <origin rpy="0 0 0" xyz="0.018 0 0.004"/>
      <geometry>
        <box size="0.045 0.04 0.023"/>
      </geometry>
    </collision>
    <inertial>
      <mass value="0.006965"/>
      <origin rpy="0 0 0" xyz="0.018 0 0.004"/>
      <!-- Inertial Axes -->
      <inertia ixx="1.48238416667e-06" ixy="0" ixz="0" iyx="0" iyy="1.48238416667e-06" iyz="0" izx="0" izy="0" izz="2.10401041667e-06"/>
    </inertial>
  </link>
  <link name="r_ankle">
    <visual>
      <origin rpy="0 0 0" xyz="0.0 0.0 0.0"/>
      <geometry>
        <mesh filename="package://plen_ros/meshes_bin/rankle.stl" scale="0.001 0.001 0.001"/>
      </geometry>
      <material name="green_mat">
        <color rgba="0.42 0.05 0.68 1"/>
      </material>
    </visual>
    <collision>
      <origin rpy="0 0 0" xyz="0.007 -0.007 -0.014"/>
      <geometry>
        <box size="0.028 0.028 0.028"/>
      </geometry>
    </collision>
    <inertial>
      <mass value="0.04"/>
      <origin rpy="0 0 0" xyz="0.007 -0.007 -0.014"/>
      <!-- Inertial Axes -->
      <inertia ixx="5.22666666667e-06" ixy="0" ixz="0" iyx="0" iyy="5.22666666667e-06" iyz="0" izx="0" izy="0" izz="5.22666666667e-06"/>
    </inertial>
  </link>
  <link name="r_foot">
    <!-- <contact>
      <lateral_friction value="100"/>
  </contact> -->
    <visual>
      <origin rpy="0 0 0" xyz="-0.0085 0 -0.0198"/>
      <geometry>
        <mesh filename="package://plen_ros/meshes_bin/rfoot.stl" scale="0.001 0.001 0.001"/>
      </geometry>
      <material name="red_mat">
        <color rgba="0 0 0 1"/>
      </material>
    </visual>
    <collision>
      <origin rpy="0 0 0" xyz="-0.00925 0 -0.017"/>
      <geometry>
        <mesh filename="package://plen_ros/meshes_bin/rfoot.stl" scale="0.001 0.001 0.001"/>
        <!-- <box size="0.041 0.062867 0.004"/> -->
      </geometry>
      <!-- <contact_coefficients mu="100000.0" kp="10000000.0" kd="10.0"/> -->
    </collision>
    <inertial>
      <mass value="0.015"/>
      <origin rpy="0 0 0" xyz="-0.00925 0 -0.009"/>
      <!-- Inertial Axes -->
      <inertia ixx="2.12125e-06" ixy="0" ixz="0" iyx="0" iyy="2.12125e-06" iyz="0" izx="0" izy="0" izz="7.04157461125e-06"/>
    </inertial>
  </link>
  <link name="l_hip">
    <visual>
      <origin rpy="0 0 3.14159265359" xyz="0.0 0.0 0.001"/>
      <geometry>
        <mesh filename="package://plen_ros/meshes_bin/lhip.stl" scale="0.001 0.001 0.001"/>
      </geometry>
      <material name="blue_mat">
        <color rgba="1 0.49 0 1"/>
      </material>
    </visual>
    <collision>
      <origin rpy="0 0 3.14159265359" xyz="0 0 -0.009"/>
      <geometry>
        <box size="0.025 0.035 0.018"/>
      </geometry>
    </collision>
    <inertial>
      <mass value="0.002568"/>
      <origin rpy="0 0 0" xyz="0 0 -0.009"/>
      <!-- Inertial Axes -->
      <inertia ixx="2.03086e-07" ixy="0" ixz="0" iyx="0" iyy="2.03086e-07" iyz="0" izx="0" izy="0" izz="3.959e-07"/>
    </inertial>
  </link>
  <link name="l_thigh">
    <visual>
      <origin rpy="0 1.57079632679 0" xyz="0.0 0 0.0"/>
      <geometry>
        <mesh filename="package://plen_ros/meshes_bin/rankle.stl" scale="0.001 0.001 0.001"/>
      </geometry>
      <material name="green_mat">
        <color rgba="0.42 0.05 0.68 1"/>
      </material>
    </visual>
    <collision>
      <origin rpy="0 1.57079632679 0" xyz="-0.014 -0.007 -0.007"/>
      <geometry>
        <box size="0.028 0.028 0.028"/>
      </geometry>
    </collision>
    <inertial>
      <mass value="0.04"/>
      <origin rpy="0 0 0" xyz="-0.014 -0.007 -0.007"/>
      <!-- Inertial Axes -->
      <inertia ixx="5.22666666667e-06" ixy="0" ixz="0" iyx="0" iyy="5.22666666667e-06" iyz="0" izx="0" izy="0" izz="5.22666666667e-06"/>
    </inertial>
  </link>
  <link name="l_knee">
    <visual>
      <origin rpy="0 0 0" xyz="0.0 0.0 0.0"/>
      <geometry>
        <mesh filename="package://plen_ros/meshes_bin/lknee.stl" scale="0.001 0.001 0.001"/>
      </geometry>
      <material name="red_mat">
        <color rgba="0 0 0 1"/>
      </material>
    </visual>
    <collision>
      <origin rpy="0 0 0" xyz="0.0175 -0.001 0.0"/>
      <geometry>
        <box size="0.038 0.03 0.024"/>
      </geometry>
    </collision>
    <inertial>
      <mass value="0.005004"/>
      <origin rpy="0 0 0" xyz="0.0175 -0.001 0.0"/>
      <!-- Inertial Axes -->
      <inertia ixx="8.4234e-07" ixy="0" ixz="0" iyx="0" iyy="8.4234e-07" iyz="0" izx="0" izy="0" izz="9.77448e-07"/>
    </inertial>
  </link>
  <link name="l_knee_servo">
    <visual>
      <origin rpy="0 0 3.14159265359" xyz="0 0 0"/>
      <geometry>
        <mesh filename="package://plen_ros/meshes_bin/servo.stl" scale="0.001 0.001 0.001"/>
      </geometry>
      <material name="blue_mat">
        <color rgba="1 0.49 0 1"/>
      </material>
    </visual>
    <collision>
      <origin rpy="0 0 3.14159265359" xyz="0 0.00625 0.0"/>
      <geometry>
        <box size="0.012 0.025 0.025"/>
      </geometry>
    </collision>
    <inertial>
      <mass value="0.012"/>
      <origin rpy="0 0 0" xyz="0 0.00625 0.0"/>
      <!-- Inertial Axes -->
      <inertia ixx="7.69e-07" ixy="0" ixz="0" iyx="0" iyy="7.69e-07" iyz="0" izx="0" izy="0" izz="7.69e-07"/>
    </inertial>
  </link>
  <link name="l_shin">
    <visual>
      <origin rpy="0 0 0" xyz="-0.0169 0 -0.0091"/>
      <geometry>
        <mesh filename="package://plen_ros/meshes_bin/rshin.stl" scale="0.001 0.001 0.001"/>
      </geometry>
      <material name="blue_mat">
        <color rgba="1 0.49 0 1"/>
      </material>
    </visual>
    <collision>
      <origin rpy="0 0 0" xyz="-0.018 0 0.004"/>
      <geometry>
        <box size="0.045 0.04 0.023"/>
      </geometry>
    </collision>
    <inertial>
      <mass value="0.006965"/>
      <origin rpy="0 0 0" xyz="-0.018 0 0.004"/>
      <!-- Inertial Axes -->
      <inertia ixx="1.48238416667e-06" ixy="0" ixz="0" iyx="0" iyy="1.48238416667e-06" iyz="0" izx="0" izy="0" izz="2.10401041667e-06"/>
    </inertial>
  </link>
  <link name="l_ankle">
    <visual>
      <origin rpy="0 0 0" xyz="-0.0075 0.0 -0.0075"/>
      <geometry>
        <mesh filename="package://plen_ros/meshes_bin/rthigh.stl" scale="0.001 0.001 0.001"/>
      </geometry>
      <material name="green_mat">
        <color rgba="0.42 0.05 0.68 1"/>
      </material>
    </visual>
    <collision>
      <origin rpy="0 0 0" xyz="-0.007 0.0 0.007"/>
      <geometry>
        <box size="0.028 0.028 0.028"/>
      </geometry>
    </collision>
    <inertial>
      <mass value="0.04"/>
      <origin rpy="0 0 0" xyz="-0.007 0.0 0.007"/>
      <!-- Inertial Axes -->
      <inertia ixx="5.22666666667e-06" ixy="0" ixz="0" iyx="0" iyy="5.22666666667e-06" iyz="0" izx="0" izy="0" izz="5.22666666667e-06"/>
    </inertial>
  </link>
  <link name="l_foot">
   <!--  <contact>
      <lateral_friction value="100"/>
  </contact> -->
    <visual>
      <origin rpy="0 0 0" xyz="0.00885 0 -0.0142"/>
      <geometry>
        <mesh filename="package://plen_ros/meshes_bin/lfoot.stl" scale="0.001 0.001 0.001"/>
      </geometry>
      <material name="red_mat">
        <color rgba="0 0 0 1"/>
      </material>
    </visual>
    <collision>
      <origin rpy="0 0 0" xyz="0.00925 0 -0.017"/>
      <geometry>
        <mesh filename="package://plen_ros/meshes_bin/lfoot.stl" scale="0.001 0.001 0.001"/>
        <!-- <box size="0.041 0.062867 0.004"/> -->
      </geometry>
      <!-- <contact_coefficients mu="100000.0" kp="10000000.0" kd="10.0"/> -->
    </collision>
    <inertial>
      <mass value="0.015"/>
      <origin rpy="0 0 0" xyz="0.00925 0 -0.009"/>
      <!-- Inertial Axes -->
      <inertia ixx="2.12125e-06" ixy="0" ixz="0" iyx="0" iyy="2.12125e-06" iyz="0" izx="0" izy="0" izz="7.04157461125e-06"/>
    </inertial>
  </link>
  <joint name="torso_batter" type="fixed">
    <origin rpy="0 0 0" xyz="-0.036 0 -0.012"/>
    <parent link="torso"/>
    <child link="battery"/>
  </joint>
  <joint name="torso_head" type="fixed">
    <origin rpy="0 0 0" xyz="-0.0065 0 0.056"/>
    <parent link="torso"/>
    <child link="head"/>
  </joint>
  <joint name="torso_rt_servo" type="fixed">
    <origin rpy="-1.57079632679 0 3.14159265359" xyz="-0.0066 -0.022 0.0308"/>
    <parent link="torso"/>
    <child link="rt_servo"/>
  </joint>
  <joint name="torso_lt_servo" type="fixed">
    <origin rpy="-1.57079632679 0 0" xyz="-0.0066 0.022 0.0308"/>
    <parent link="torso"/>
    <child link="lt_servo"/>
  </joint>
  <joint name="torso_rb_servo" type="fixed">
    <origin rpy="3.14159265359 0 3.14159265359" xyz="-0.0066 -0.0228 -0.02475"/>
    <parent link="torso"/>
    <child link="rb_servo"/>
  </joint>
  <joint name="torso_lb_servo" type="fixed">
    <origin rpy="3.14159265359 0 0" xyz="-0.0066 0.0228 -0.02475"/>
    <parent link="torso"/>
    <child link="lb_servo"/>
  </joint>
  <joint name="torso_r_shoulder" type="revolute">
    <axis xyz="0 0 1"/>
    <origin rpy="1.57079632679 -1.57079632679 0" xyz="-0.0066 -0.038 0.0308"/>
    <parent link="torso"/>
    <child link="r_shoulder"/>
    <limit effort="0.15" lower="-1.7" upper="1.7" velocity="8.0"/>
    <joint_properties damping="1" friction="1"/>
  </joint>
  <joint name="r_shoulder_rs_servo" type="revolute">
    <axis xyz="0 0 1"/>
    <origin rpy="-1.57079632679 1.57079632679 0" xyz="-0.00535 0.0006 0.01265"/>
    <parent link="r_shoulder"/>
    <child link="rs_servo"/>
    <limit effort="0.15" lower="-1.7" upper="1.7" velocity="8.0"/>
    <joint_properties damping="1" friction="1"/>
  </joint>
  <joint name="rs_servo_r_arm" type="fixed">
    <origin rpy="-1.57079632679 0 0" xyz="0.0 0.0195 -0.002"/>
    <parent link="rs_servo"/>
    <child link="r_arm"/>
  </joint>
  <joint name="r_arm_re_servo" type="fixed">
    <origin rpy="-1.57079632679 0 0" xyz="0.0 0.002 0.0195"/>
    <parent link="r_arm"/>
    <child link="re_servo"/>
  </joint>
  <joint name="re_servo_r_elbow" type="revolute">
    <axis xyz="0 1 0"/>
    <origin rpy="-1.57079632679 0 1.57079632679" xyz="0.0 0.0 -0.0015"/>
    <parent link="re_servo"/>
    <child link="r_elbow"/>
    <limit effort="0.15" lower="-1.7" upper="1.7" velocity="8.0"/>
    <joint_properties damping="1" friction="1"/>
  </joint>
  <joint name="r_elbow_r_hand" type="fixed">
    <origin rpy="3.14159265359 1.57079632679 0" xyz="-0.03 0.0 0.0"/>
    <parent link="r_elbow"/>
    <child link="r_hand"/>
  </joint>
  <joint name="torso_l_shoulder" type="revolute">
    <axis xyz="0 0 1"/>
    <origin rpy="-1.57079632679 -1.57079632679 0" xyz="-0.0066 0.038 0.0308"/>
    <parent link="torso"/>
    <child link="l_shoulder"/>
    <limit effort="0.15" lower="-1.7" upper="1.7" velocity="8.0"/>
    <joint_properties damping="1" friction="1"/>
  </joint>
  <joint name="l_shoulder_ls_servo" type="revolute">
    <axis xyz="0 0 1"/>
    <origin rpy="-1.57079632679 1.57079632679 0" xyz="-0.00535 0.0006 0.01265"/>
    <parent link="l_shoulder"/>
    <child link="ls_servo"/>
    <limit effort="0.15" lower="-1.7" upper="1.7" velocity="8.0"/>
    <joint_properties damping="1" friction="1"/>
  </joint>
  <joint name="ls_servo_l_arm" type="fixed">
    <origin rpy="-1.57079632679 0 0" xyz="0.0 0.0195 -0.002"/>
    <parent link="ls_servo"/>
    <child link="l_arm"/>
  </joint>
  <joint name="l_arm_le_servo" type="fixed">
    <origin rpy="-1.57079632679 0 0" xyz="0.0 0.002 0.0195"/>
    <parent link="l_arm"/>
    <child link="le_servo"/>
  </joint>
  <joint name="le_servo_l_elbow" type="revolute">
    <axis xyz="0 1 0"/>
    <origin rpy="-1.57079632679 0 1.57079632679" xyz="0.0 0.0 -0.0015"/>
    <parent link="le_servo"/>
    <child link="l_elbow"/>
    <limit effort="0.15" lower="-1.7" upper="1.7" velocity="8.0"/>
    <joint_properties damping="1" friction="1"/>
  </joint>
  <joint name="l_elbow_l_hand" type="fixed">
    <origin rpy="3.14159265359 1.57079632679 0" xyz="-0.03 0.0 0.0"/>
    <parent link="l_elbow"/>
    <child link="l_hand"/>
  </joint>
  <joint name="rb_servo_r_hip" type="revolute">
    <axis xyz="0 0 1"/>
    <origin rpy="3.14159265359 0 1.57079632679" xyz="0.0 0.0 0.0142"/>
    <parent link="rb_servo"/>
    <child link="r_hip"/>
    <limit effort="0.15" lower="-1.7" upper="1.7" velocity="8.0"/>
    <joint_properties damping="1" friction="1"/>
  </joint>
  <joint name="r_hip_r_thigh" type="revolute">
    <axis xyz="0 1 0"/>
    <origin rpy="3.14159265359 0 0" xyz="0.00545 -0.002 -0.01281"/>
    <parent link="r_hip"/>
    <child link="r_thigh"/>
    <limit effort="0.15" lower="-1.7" upper="1.7" velocity="8.0"/>
    <joint_properties damping="1" friction="1"/>
  </joint>
  <joint name="r_thigh_r_knee" type="revolute">
    <axis xyz="0 1 0"/>
    <origin rpy="1.57079632679 -1.57079632679 0" xyz="-0.023 0.0075 0.01275"/>
    <parent link="r_thigh"/>
    <child link="r_knee"/>
    <limit effort="0.15" lower="-1.7" upper="1.7" velocity="8.0"/>
    <joint_properties damping="1" friction="1"/>
  </joint>
  <joint name="r_knee_knee_servo" type="fixed">
    <origin rpy="-1.57079632679 0 0" xyz="0.028 -0.0128 0.0005"/>
    <parent link="r_knee"/>
    <child link="r_knee_servo"/>
  </joint>
  <joint name="r_knee_r_shin" type="revolute">
    <axis xyz="0 1 0"/>
    <origin rpy="0 0 0" xyz="0.0281 -0.0146 0.00045"/>
    <parent link="r_knee"/>
    <child link="r_shin"/>
    <limit effort="0.15" lower="-1.7" upper="1.7" velocity="8.0"/>
    <joint_properties damping="1" friction="1"/>
  </joint>
  <joint name="r_shin_r_ankle" type="revolute">
    <axis xyz="0 0 1"/>
    <origin rpy="-1.57079632679 -1.57079632679 3.14159265359" xyz="0.03375 -0.017 0.0"/>
    <parent link="r_shin"/>
    <child link="r_ankle"/>
    <limit effort="0.15" lower="-1.7" upper="1.7" velocity="8.0"/>
    <joint_properties damping="1" friction="1"/>
  </joint>
  <joint name="r_ankle_r_foot" type="revolute">
    <axis xyz="0 1 0"/>
    <origin rpy="-1.57079632679 -1.57079632679 0" xyz="0.0042 -0.0127 -0.0074"/>
    <parent link="r_ankle"/>
    <child link="r_foot"/>
    <limit effort="0.15" lower="-1.7" upper="1.7" velocity="8.0"/>
    <joint_properties damping="1" friction="1"/>
  </joint>
  <joint name="lb_servo_l_hip" type="revolute">
    <axis xyz="0 0 1"/>
    <origin rpy="3.14159265359 0 1.57079632679" xyz="0.0 0.0 0.0142"/>
    <parent link="lb_servo"/>
    <child link="l_hip"/>
    <limit effort="0.15" lower="-1.7" upper="1.7" velocity="8.0"/>
    <joint_properties damping="1" friction="1"/>
  </joint>
  <joint name="l_hip_l_thigh" type="revolute">
    <axis xyz="1 0 0"/>
    <origin rpy="1.57079632679 0 1.57079632679" xyz="0.0055 0.017 -0.01265"/>
    <parent link="l_hip"/>
    <child link="l_thigh"/>
    <limit effort="0.15" lower="-1.7" upper="1.7" velocity="8.0"/>
    <joint_properties damping="1" friction="1"/>
  </joint>
  <joint name="l_thigh_l_knee" type="revolute">
    <axis xyz="0 1 0"/>
    <origin rpy="-1.57079632679 0 -1.57079632679" xyz="-0.0074 -0.0128 -0.0086"/>
    <parent link="l_thigh"/>
    <child link="l_knee"/>
    <limit effort="0.15" lower="-1.7" upper="1.7" velocity="8.0"/>
    <joint_properties damping="1" friction="1"/>
  </joint>
  <joint name="l_knee_knee_servo" type="fixed">
    <origin rpy="-1.57079632679 3.14159265359 0" xyz="0.028 0.00145 0.0"/>
    <parent link="l_knee"/>
    <child link="l_knee_servo"/>
  </joint>
  <joint name="l_knee_l_shin" type="revolute">
    <axis xyz="0 1 0"/>
    <origin rpy="0 3.14159265359 0" xyz="0.0281 -0.0002 0.00045"/>
    <parent link="l_knee"/>
    <child link="l_shin"/>
    <limit effort="0.15" lower="-1.7" upper="1.7" velocity="8.0"/>
    <joint_properties damping="1" friction="1"/>
  </joint>
  <joint name="l_shin_l_ankle" type="revolute">
    <axis xyz="0 1 0"/>
    <origin rpy="3.14159265359 1.57079632679 0" xyz="-0.03375 -0.002 0.0"/>
    <parent link="l_shin"/>
    <child link="l_ankle"/>
    <limit effort="0.15" lower="-1.7" upper="1.7" velocity="8.0"/>
    <joint_properties damping="1" friction="1"/>
  </joint>
  <joint name="l_ankle_l_foot" type="revolute">
    <axis xyz="0 1 0"/>
    <origin rpy="3.14159265359 0 -1.57079632679" xyz="-0.0042 0.0075 0.0128"/>
    <parent link="l_ankle"/>
    <child link="l_foot"/>
    <limit effort="0.15" lower="-1.7" upper="1.7" velocity="8.0"/>
    <joint_properties damping="1" friction="1"/>
  </joint>
</robot>
